Workbook

Sheet INFO
A1: Scenario Description | B1: Example scenario
A3: This Excel file defines an oemof energy system.
A4: The components are defined in the several sheets.
A6: Sheet | B6: Notes
A7: buses | B7: Defines the buses used in the energy system
B8: -If excess or shortage flag is set (=1), an additional sink resp. source is added AUTOMATICALLY
A9: commodity_sources | B9: Defines the commodity sources such as oil, gas etc.
A10: demand | B10: Defines demand components such as heat demand
A11: powerlines | B11: Defines power lines between 2 buses
B12: -Creates 2 oemof transformers (A->B, B->A)
A13: renewables | B13: Defines the renewable sources (fixed generation)
A14: storages | B14: Defines storages
B15: Initial capacity: set between 0 (empty) and 1 (full)
A16: transformers | B16: Defines the transformers like power2gas plants etc.
B17: -variable costs refer to input values!
B18: - capacity is the nominal value of the output; "max nom in" is the maximum input which is multiplied with the timeseries transformer.max
B19: -Power lines are defined in the sheet "powerlines"
A20: time_series | B20: Time series
B21: -Format of column must follow the format NODE.PARAMETER (e.g. wind.actual_value)
B22: time series are implemented for renewables, demands and transformer inputs
A24: General notes
A25: -For details on how this data is used (and to alter) during creation of the energy system refer to function "create_nodes()".
A26: -Unit of values is kW / kWh and €
A27: -If column "active" is set to 0, the component will not be created in the energy system

Sheet buses
A1: label | B1: active | C1: excess | D1: shortage | E1: unit | F1: shortage_costs | G1: shortage_env | H1: excess_costs | I1: excess_env | J1: excess_env_conversion | K1: warnings | L1: Dropdown list | N1: c_avar_25 | O1: c_avar_30 | P1: c_avar_35 | Q1: c_avar_40 | R1: c_avar_45 | S1: c_avar_50 | T1: c_avar_55 | U1: c_avar_60 | V1: c_avar_65 | W1: c_avar_70
A2: bus_el | B2: 1 | C2: 1 | D2: 0 | E2: kWh | F2: 0 | G2: empty | H2: 0 | I2: empty | J2: 0 | K2: =IF(AND(I2<>"empty",J2=0),"define excess_env_conversion","") | L2: empty | M2: electricity excess, low voltage, DE, commodity_kWh
A3: bus_el-over | B3: 1 | C3: 1 | D3: 0 | E3: kWh | F3: 0 | G3: empty | H3: 0 | I3: empty | J3: 0 | K3: =IF(AND(I3<>"empty",J3=0),"define excess_env_conversion","") | L3: empty
A4: bus_el-h2 | B4: 1 | C4: 1 | D4: 0 | E4: kWh | F4: 0 | G4: empty | H4: 0 | I4: empty | J4: 0 | K4: =IF(AND(I4<>"empty",J4=0),"define excess_env_conversion","") | L4: empty
A5: bus_el-re | B5: 1 | C5: 1 | D5: 0 | E5: kWh | F5: 0 | G5: empty | H5: 0 | I5: empty | J5: 0 | K5: =IF(AND(I5<>"empty",J5=0),"define excess_env_conversion","") | L5: empty
A6: bus_el-stor | B6: 1 | C6: 1 | D6: 0 | E6: kWh | F6: 0 | G6: empty | H6: 0 | I6: empty | J6: 0 | K6: =IF(AND(I6<>"empty",J6=0),"define excess_env_conversion","") | L6: empty
A7: bus_el-out | B7: 1 | C7: 0 | D7: 0 | E7: kWh | F7: 0 | G7: empty | H7: 0 | I7: empty | J7: 0 | K7: =IF(AND(I7<>"empty",J7=0),"define excess_env_conversion","") | L7: empty
A8: bus_el-grid | B8: 1 | C8: 0 | D8: 0 | E8: kWh | F8: 0 | G8: empty | H8: 0 | I8: empty | J8: 0 | K8: =IF(AND(I8<>"empty",J8=0),"define excess_env_conversion","") | L8: empty
A9: bus_el-transformed | B9: 1 | C9: 1 | D9: 0 | E9: kWh | F9: 0 | G9: empty | H9: 0 | I9: empty | J9: 0 | K9: =IF(AND(I9<>"empty",J9=0),"define excess_env_conversion","") | L9: empty
A10: bus_th | B10: 0 | C10: 0 | D10: 0 | E10: kWh | F10: 0 | G10: empty | H10: 0 | I10: empty | J10: 0 | K10: =IF(AND(I10<>"empty",J10=0),"define excess_env_conversion","") | L10: empty
A11: bus_th_low | B11: 0 | C11: 0 | D11: 0 | E11: kWh | F11: 1000000000 | G11: empty | H11: 0 | I11: empty | J11: 0 | K11: =IF(AND(I11<>"empty",J11=0),"define excess_env_conversion","") | L11: empty
A12: bus_th_high | B12: 0 | C12: 0 | D12: 0 | E12: kWh | F12: 0 | G12: empty | H12: 0 | I12: empty | J12: 0 | K12: =IF(AND(I12<>"empty",J12=0),"define excess_env_conversion","") | L12: empty
A13: bus_th_households | B13: 0 | C13: 0 | D13: 0 | E13: kWh | F13: 0 | G13: empty | H13: 0 | I13: empty | J13: 0 | K13: =IF(AND(I13<>"empty",J13=0),"define excess_env_conversion","") | L13: empty
A14: bus_logs | B14: 0 | C14: 0 | D14: 0 | E14: kWh | F14: 0 | G14: empty | H14: 0 | I14: empty | J14: 0 | K14: =IF(AND(I14<>"empty",J14=0),"define excess_env_conversion","") | L14: empty
... A22: bus_hydrogen_proxy | B22: 1 | C22: 1 | D22: 0 | E22: kg | F22: 0 | G22: empty | H22: 0 | I22: empty | J22: 0 | K22: =IF(AND(I22<>"empty",J22=0),"define excess_env_conversion","") | L22: empty
A23: bus_biogas | B23: 0 | C23: 0 | D23: 0 | E23: kWh | F23: 0 | G23: empty | H23: 0 | I23: empty | J23: 0 | L23: empty
A24: bus_biometh | B24: 1 | C24: 1 | D24: 0 | E24: kWh | F24: 0 | G24: empty | H24: 0 | I24: empty | J24: 0 | L24: empty
A25: bus_oxygen | B25: 1 | C25: 1 | D25: 0 | E25: kg | F25: 0 | G25: empty | H25: 0 | I25: empty | J25: 0 | K25: =IF(AND(I25<>"empty",J25=0),"define excess_env_conversion","") | L25: empty
A26: bus_water_ultrapure | B26: 1 | C26: 1 | D26: 0 | E26: kg | F26: 0 | G26: empty | H26: 0 | I26: empty | J26: 0 | K26: =IF(AND(I26<>"empty",J26=0),"define excess_env_conversion","") | L26: empty
A27: bus_water_deionized | B27: 1 | C27: 1 | D27: 0 | E27: kg | F27: 0 | G27: empty | H27: 0 | I27: empty | J27: 0 | K27: =IF(AND(I27<>"empty",J27=0),"define excess_env_conversion","") | L27: empty
A28: bus_th60 | B28: 1 | C28: 1 | D28: 0 | E28: kWh | F28: 0 | G28: empty | H28: 0 | I28: empty | J28: 0 | L28: empty
A29: bus_th120 | B29: 1 | C29: 0 | D29: 0 | E29: kWh | F29: 0 | G29: empty | H29: 0 | I29: empty | J29: 0 | L29: empty
A30: bus_th200 | B30: 1 | C30: 0 | D30: 0 | E30: kWh | F30: 0 | G30: empty | H30: 0 | I30: empty | J30: 0 | L30: empty
A31: bus_th400 | B31: 1 | C31: 0 | D31: 0 | E31: kWh | F31: 0 | G31: empty | H31: 0 | I31: empty | J31: 0 | L31: empty
A32: bus_lohc | B32: 1 | C32: 1 | D32: 0 | E32: kg | F32: 0 | G32: empty | H32: 0 | I32: empty | J32: 0 | L32: empty
A33: bus_nh3 | B33: 1 | C33: 1 | D33: 0 | E33: kg | F33: 0 | G33: empty | H33: 0 | I33: empty | J33: 0 | L33: empty
A34: bus_atr-exhaust | B34: 1 | C34: 0 | D34: 0 | E34: kg | F34: 0 | G34: empty | H34: 0 | I34: empty | J34: 0 | L34: empty
A35: bus_smr-exhaust | B35: 1 | C35: 0 | D35: 0 | E35: kg | F35: 0 | G35: empty | H35: 0 | I35: empty | J35: 0 | L35: empty
A36: bus_co2_emission | B36: 1 | C36: 1 | D36: 0 | E36: kg | F36: 0 | G36: empty | H36: c_avar | I36: co2_emission | J36: 1 | L36: empty | M36: co2_emission | N36: 0.075 | O36: 0.15 | P36: 0.225 | Q36: 0.3 | R36: 0.3 | S36: 0.3 | T36: 0.3 | U36: 0.3 | V36: 0.3 | W36: 0.3
A37: bus_co2 | B37: 1 | C37: 1 | D37: 0 | E37: kg | F37: 0 | G37: empty | H37: c_avar | I37: empty | J37: 0 | L37: empty | N37: =0.4*N36 -> 0.03 | O37: =0.4*O36 -> 0.06 | P37: =0.4*P36 -> 0.09 | Q37: =0.4*Q36 -> 0.12 | R37: =0.4*R36 -> 0.12 | S37: =0.4*S36 -> 0.12 | T37: =0.4*T36 -> 0.12 | U37: =0.4*U36 -> 0.12 | ... W37: =0.4*W36 -> 0.12
A38: bus_carbon | B38: 1 | C38: 1 | D38: 0 | E38: kWh | F38: 0 | G38: empty | H38: 0 | I38: empty | J38: 0 | L38: empty
A39: bus_co | B39: 0 | C39: 0 | D39: 0 | E39: kg | F39: 0 | G39: empty | H39: 0 | I39: empty | J39: 0 | L39: empty
A40: bus_steam7,5bar | B40: 1 | C40: 1 | D40: 0 | E40: kWh | F40: 0 | G40: empty | H40: 0 | I40: empty | J40: 0 | L40: empty
A41: bus_ch3oh | B41: 0 | C41: 0 | D41: 0 | E41: kg | F41: 0 | G41: empty | H41: 0 | I41: empty | J41: 0 | L41: empty
A42: bus_smre | B42: 1 | C42: 0 | D42: 0 | E42: kg | F42: 0 | G42: empty | H42: 0 | I42: empty | J42: 0 | L42: empty
A43: bus_smre_po1 | B43: 1 | C43: 0 | D43: 0 | E43: kg | F43: 0 | G43: empty | H43: 0 | I43: empty | J43: 0 | L43: empty
A44: bus_smr_pi1 | B44: 1 | C44: 0 | D44: 0 | E44: kg | F44: 0 | G44: empty | H44: 0 | I44: empty | J44: 0 | L44: empty
A45: bus_smr_pi2 | B45: 1 | C45: 0 | D45: 0 | E45: kg | F45: 0 | G45: empty | H45: 0 | I45: empty | J45: 0 | L45: empty
A46: bus_smr_po1 | B46: 1 | C46: 0 | D46: 0 | E46: kg | F46: 0 | G46: empty | H46: 0 | I46: empty | J46: 0 | L46: empty
A47: bus_pem | B47: 1 | C47: 0 | D47: 0 | E47: kg | F47: 0 | G47: empty | H47: 0 | I47: empty | J47: 0 | L47: empty
...

Sheet commodity_sources
A1: label | B1: active | C1: to | D1: unit | E1: year_of_availability | F1: end_of_availability | G1: variable_costs | H1: var_env1 | I1: var_env1_conversion | J1: timevariable_costs | K1: max | L1: comment | M1: fuel_based | N1: comment
A2: resource_grid_25 | B2: 1 | C2: bus_el-grid | D2: kWh | E2: 2025 | F2: 2030 | G2: 0.1 | H2: el_mix_DE_2025_kWh | I2: 1 | J2: 0 | M2: 1 | N2: baseline assumptions: Langfristszenarien; bdew2023a p. 44 (Futures 2026: 0,112); Prognos
A3: resource_grid_30 | B3: 1 | C3: bus_el-grid | D3: kWh | E3: 2030 | F3: 2035 | G3: 0.08 | H3: el_mix_DE_2030_kWh | I3: 1 | J3: 0
A4: resource_grid_35 | B4: 1 | C4: bus_el-grid | D4: kWh | E4: 2035 | F4: 2040 | G4: 0.07 | H4: el_mix_DE_2035_kWh | I4: 1 | J4: 0
A5: resource_grid_40 | B5: 1 | C5: bus_el-grid | D5: kWh | E5: 2040 | F5: 2045 | G5: 0.06 | H5: el_mix_DE_2040_kWh | I5: 1 | J5: 0
A6: resource_grid_45 | B6: 1 | C6: bus_el-grid | D6: kWh | E6: 2045 | F6: 2050 | G6: 0.055 | H6: el_mix_DE_2045_kWh | I6: 1 | J6: 0
A7: resource_grid_50 | B7: 1 | C7: bus_el-grid | D7: kWh | E7: 2050 | F7: 2055 | G7: 0.055 | H7: el_mix_DE_2045_kWh | I7: 1 | J7: 0
A8: resource_grid_55 | B8: 0 | C8: bus_el-grid | D8: kWh | E8: 2055 | F8: 2060 | G8: 0.055 | H8: el_mix_DE_2045_kWh | I8: 1 | J8: 0
A9: resource_grid_60 | B9: 0 | C9: bus_el-grid | D9: kWh | E9: 2060 | F9: 2065 | G9: 0.055 | H9: el_mix_DE_2045_kWh | I9: 1 | J9: 0
A10: resource_grid_65 | B10: 0 | C10: bus_el-grid | D10: kWh | E10: 2065 | F10: 2070 | G10: 0.055 | H10: el_mix_DE_2045_kWh | I10: 1 | J10: 0
A11: resource_grid_70 | B11: 0 | C11: bus_el-grid | D11: kWh | E11: 2070 | F11: 1000000000000 | G11: 0.055 | H11: el_mix_DE_2045_kWh | I11: 1 | J11: 0
A13: resource_nat_gas_25 | B13: 0 | C13: bus_nat_gas | D13: kWh | E13: 2025 | F13: 2030 | G13: 0.042 | H13: market for natural gas, high pressure_commodity_DE_m3 | I13: =1/(36/3.6) -> 0.1 | J13: 0 | L13: 36 MJ/m3 [ecoinvent database] | M13: 1 | N13: based on Bundesnetzagentur für Elektrizität…2022 p. 460, statista (download), TradingHub.eu and Langfristszenarien; bdew2023b;
A14: resource_nat_gas_30 | B14: 0 | C14: bus_nat_gas | D14: kWh | E14: 2030 | F14: 2035 | G14: 0.03 | H14: market for natural gas, high pressure_commodity_DE_m3 | I14: =1/(36/3.6) -> 0.1 | J14: 0 | M14: 1 | N14: based on Langfristszenarien
A15: resource_nat_gas_35 | B15: 0 | C15: bus_nat_gas | D15: kWh | E15: 2035 | F15: 2040 | G15: 0.019 | H15: market for natural gas, high pressure_commodity_DE_m3 | I15: =1/(36/3.6) -> 0.1 | J15: 0 | M15: 1 | N15: based on Langfristszenarien
A16: resource_nat_gas_40 | B16: 0 | C16: bus_nat_gas | D16: kWh | E16: 2040 | F16: 2045 | G16: 0.019 | H16: market for natural gas, high pressure_commodity_DE_m3 | I16: =1/(36/3.6) -> 0.1 | J16: 0 | M16: 1 | N16: based on Langfristszenarien
A17: resource_nat_gas_45 | B17: 0 | C17: bus_nat_gas | D17: kWh | E17: 2045 | F17: 2050 | G17: 10 | H17: market for natural gas, high pressure_commodity_DE_m3 | I17: =1/(36/3.6) -> 0.1 | J17: 0 | M17: 1 | N17: based on Langfristszenarien
A18: resource_nat_gas_50 | B18: 0 | C18: bus_nat_gas | D18: kWh | E18: 2050 | F18: 2055 | G18: 10 | H18: market for natural gas, high pressure_commodity_DE_m3 | I18: =1/(36/3.6) -> 0.1 | J18: 0
A19: resource_nat_gas_55 | B19: 0 | C19: bus_nat_gas | D19: kWh | E19: 2055 | F19: 2060 | G19: 10 | H19: market for natural gas, high pressure_commodity_DE_m3 | I19: =1/(36/3.6) -> 0.1 | J19: 0
A20: resource_nat_gas_60 | B20: 0 | C20: bus_nat_gas | D20: kWh | E20: 2060 | F20: 2065 | G20: 10 | H20: market for natural gas, high pressure_commodity_DE_m3 | I20: =1/(36/3.6) -> 0.1 | J20: 0
A21: resource_nat_gas_65 | B21: 0 | C21: bus_nat_gas | D21: kWh | E21: 2065 | F21: 2070 | G21: 10 | H21: market for natural gas, high pressure_commodity_DE_m3 | I21: =1/(36/3.6) -> 0.1 | J21: 0
A22: resource_nat_gas_70 | B22: 0 | C22: bus_nat_gas | D22: kWh | E22: 2070 | F22: 2075 | G22: 10 | H22: market for natural gas, high pressure_commodity_DE_m3 | I22: =1/(36/3.6) -> 0.1 | J22: 0
A24: resource_biogas_25 | B24: 0 | C24: bus_biogas | D24: kWh | E24: 2025 | F24: 2030 | G24: 0.09 | H24: empty | I24: 1 | J24: 0 | L24: biomethane price, biogas could be cheaper to a small extent | M24: 0 | N24: Alberici2023,
A25: resource_biogas_30 | B25: 0 | C25: bus_biogas | D25: kWh | E25: 2030 | F25: 2035 | G25: 0.09 | H25: empty | I25: 1 | J25: 0 | L25: biomethane price, biogas could be cheaper to a small extent | M25: 0
A26: resource_biogas_35 | B26: 0 | C26: bus_biogas | D26: kWh | E26: 2035 | F26: 2040 | G26: 0.09 | H26: empty | I26: 1 | J26: 0 | L26: biomethane price, biogas could be cheaper to a small extent | M26: 0
A27: resource_biogas_40 | B27: 0 | C27: bus_biogas | D27: kWh | E27: 2040 | F27: 2045 | G27: 0.09 | H27: empty | I27: 1 | J27: 0 | L27: biomethane price, biogas could be cheaper to a small extent | M27: 0
A28: resource_biogas_45 | B28: 0 | C28: bus_biogas | D28: kWh | E28: 2045 | F28: 1000000000000 | G28: 0.09 | H28: empty | I28: 1 | J28: 0 | L28: biomethane price, biogas could be cheaper to a small extent | M28: 0
A29: resource_biogas | B29: 0 | C29: bus_biogas | D29: kWh | G29: 0.09 | H29: empty | I29: 1 | J29: 0 | L29: biomethane price, biogas could be cheaper to a small extent | M29: 0
A30: resource_biometh_industry | B30: 0 | C30: bus_biometh | D30: kWh | E30: 0 | F30: 1000000000000 | G30: 0.1152 | H30: empty | I30: 3.6 | J30: 0 | L30: 3.6 MJ/kWh | M30: 1
A31: resource_pellets | B31: 0 | C31: bus_pellets | D31: kWh | E31: 0 | F31: 1000000000000 | G31: 0.32 | H31: market for wood pellet, measured as dry mass, commodity_kg | I31: =1/18.7*3.6 -> 0.19251337 | J31: 0 | L31: LHV 18.7 MJ/kg (dry mass) [ecoinvent database] | M31: 1
A32: resource_w_chips | B32: 0 | C32: bus_w_chips | D32: kWh | E32: 0 | F32: 1000000000000 | G32: =315/1000*(1/0.9)*(1/18.7)*3.6 -> 0.067379679 | H32: market for wood chips, measured as dry mass_commodity_kg | I32: =1/18.9*3.6 -> 0.19047619 | J32: 0 | L32: LHV 18.9 MJ/kg (dry mass) | M32: 1
A33: resource_hw_chips | B33: 0 | C33: bus_hw_chips | D33: kWh | E33: 0 | F33: 1000000000000 | G33: =121.6/1000*(1/0.8)*(1/18.9)*3.6 -> 0.028952381 | H33: market for hard_softwood chips from forest, wet, measured as dry mass, commodity_kg | I33: =1/18.3*3.6 -> 0.19672131 | J33: 0 | L33: LHV (oven-dry) 18.3 MJ/kg [ecoinvent database] | M33: 1
A34: resource_sw_chips | B34: 0 | C34: bus_sw_chips | D34: kWh | E34: 0 | F34: 1000000000000 | G34: =305*4/3580*(1/0.8)*(1/18.55)*3.6 -> 0.082669518 | H34: market for hard_softwood chips from forest, wet, measured as dry mass, commodity_kg | I34: =1/19.1*3.6 -> 0.18848168 | J34: 0 | L34: LHV (oven-dry) 19.1 MJ/kg [ecoinvent database] | M34: 1
A35: resource_logs | B35: 0 | C35: bus_logs | D35: kWh | E35: 0 | F35: 1000000000000 | G35: =77.73/1000*(1/0.65)*(1/18.3)*3.6 -> 0.023524842 | H35: market for cleft timber, measured as dry mass, commodity_DE_kg | I35: =1/18.55*3.6 -> 0.19407008 | J35: 0 | L35: LHV 18.55 MJ/kg (dry mass) [ecoinvent database] | M35: 1
A36: resource_water_ultrapure | B36: 1 | C36: bus_water_ultrapure | D36: kg | E36: 0 | F36: 1000000000000 | G36: 0.003 | H36: market for water, ultrapure | I36: 1 | J36: 0 | M36: 0
A37: resource_water_deionized | B37: 1 | C37: bus_water_deionized | D37: kg | E37: 0 | F37: 1000000000000 | G37: 0.003 | H37: market for water, deionised | I37: 1 | J37: 0 | M37: 0
A38: resource_th60-wasteheat | B38: 0 | C38: bus_th60 | D38: kWh | E38: 0 | F38: 2100 | G38: 0 | H38: empty | I38: 1 | J38: 0
A40: resource_h2-pipeline_25 | B40: 0 | C40: bus_hydrogen | D40: kg | E40: 2025 | F40: 2030 | G40: 1e+20 | H40: hydrogen pipeline import, Morocco-Germany_kg | I40: 1 | J40: 0 | L40: solely Levelized Cost of Fuel but no taxes or other charges are considered | M40: 0 | N40: extensive literature research: Aurora2023, Lux2021, Lux2020, within range of Wietschel2023; LCA based on Kanz2023
A41: resource_h2-pipeline_30 | B41: 0 | C41: bus_hydrogen | D41: kg | E41: 2030 | F41: 2035 | G41: 1e+20 | H41: hydrogen pipeline import, Morocco-Germany_kg | I41: 1 | J41: 0 | L41: solely Levelized Cost of Fuel but no taxes or other charges are considered | M41: 0 | N41: 5.16
A42: resource_h2-pipeline_35 | B42: 0 | C42: bus_hydrogen | D42: kg | E42: 2035 | F42: 2040 | G42: 4.87 | H42: hydrogen pipeline import, Morocco-Germany_kg | I42: 1 | J42: 0 | L42: solely Levelized Cost of Fuel but no taxes or other charges are considered | M42: 0 | N42: 4.87
A43: resource_h2-pipeline_40 | B43: 0 | C43: bus_hydrogen | D43: kg | E43: 2040 | F43: 2045 | G43: 4.58 | H43: hydrogen pipeline import, Morocco-Germany_kg | I43: 1 | J43: 0 | L43: solely Levelized Cost of Fuel but no taxes or other charges are considered | M43: 0 | N43: 4.58
...

Sheet demand
A1: label | B1: active | C1: from | D1: nominal value | E1: fixed-flow_periodically_variable | F1: comment
A2: load_el | B2: 1 | C2: bus_el | D2: 1 | E2: 0
A3: load_th_high | B3: 0 | C3: bus_th_high | D3: 1 | E3: 0
A4: load_th_low | B4: 0 | C4: bus_th_low | D4: 1 | E4: 0
A5: load_th | B5: 0 | C5: bus_th | D5: 1 | E5: 0
A7: load_hydrogen | B7: 1 | C7: bus_hydrogen | D7: 1 | E7: 0
A8: load_h2_export | B8: 0 | C8: bus_h2_300bar | D8: 1 | E8: 0
A9: load_steamSite | B9: 1 | C9: bus_steam7,5bar | D9: 1 | E9: 0
A10: load_methanol | B10: 0 | C10: bus_ch3oh | D10: 1 | E10: 0
A12: load-households_el | B12: 0 | C12: bus_el | D12: 1 | E12: 0
A13: load-households_th | B13: 0 | C13: bus_th_households | D13: 1 | E13: 0

Sheet renewables
A1: label | B1: active | C1: to | D1: unit | E1: initial_existance | F1: initially_installed_capacity | G1: year_of_availability | H1: end_of_availability | I1: variable_costs | J1: var_env1 | K1: var_env1_conversion | L1: om | M1: invest | N1: lifetime | O1: max_capacity_invest | P1: max_total_capacity | Q1: inv1 | R1: inv1_conversion | S1: fixed | T1: fixed-flow_periodically_variable | U1: info1 | V1: info2 | W1: info3 | Y1: comment | AA1: Dropdown list | AB1: Dropdown list | AC1: Dropdown list
U2: eg. turbine type | V2: e.g. hub height | W2: e.g. WPP capacity
A3: PV_flat_roof | B3: 0 | C3: bus_el | D3: kWp | E3: 0 | F3: 0 | G3: 0 | H3: 1000000000000 | I3: 0 | J3: empty | K3: 1 | L3: =0.02*M3 -> 41.174 | M3: =(1730*1.19) -> 2058.7 | N3: 25 | O3: 1000000000000 | P3: 1000000 | Q3: production, PV, flat-roof installation, 156kWp, cryst_2021_kW | R3: 1 | S3: 1 | AB3: construction, wind turbine, 6kW, onshore_kW | AC3: production, PV, facade installation, 3kWp, cryst_2021_kW
A5: PV_facade | B5: 0 | C5: bus_el | D5: kWp | E5: 0 | F5: 0 | G5: 0 | H5: 1000000000000 | I5: 0 | J5: empty | K5: 1 | L5: =L3 -> 41.174 | M5: =2*M3 -> 4117.4 | N5: 25 | O5: 1000000000000 | P5: 1000000 | Q5: production, PV, facade installation, 3kWp, crist_kW | R5: 1 | S5: 1 | AB5: construction, wind turbine, 3.2MW, DDPMSG, onshore_kW | AC5: production, PV, slanted-roof installation, 3kWp, cryst_2021_kW
A6: PV_roof | B6: 0 | C6: bus_el | D6: kW | E6: 0 | F6: 0 | G6: 0 | H6: 1000000000000 | I6: 0 | J6: empty | K6: 1 | L6: =0.02*M6 -> 41.174 | M6: =(1730*1.19) -> 2058.7 | N6: 25 | O6: 1000000000000 | P6: 1000000 | Q6: production, PV, slanted-roof installation, 3kWp, cryst_2021_kW | R6: 1 | S6: 1 | AB6: construction, wind turbine, 3.3MW, DFIG, onshore_kW | AC6: production, ,PV, slanted-roof installation, 3kWp, CIS_kW
A7: ambient_heat_ground | B7: 0 | C7: bus_th_ambient | D7: kW | E7: 0 | F7: 0 | G7: 0 | H7: 1000000000000 | I7: 0 | J7: empty | K7: 1 | L7: 0 | M7: =100*R7 -> 1818.1818 | N7: 50 | O7: 1000000000000 | P7: 1000000 | Q7: construction, borehole heat exchanger, investment_m | R7: =1/Y7 -> 18.181818 | S7: 0 | Y7: 0.055 | Z7: kW/m lt. Energiekonzept "Am Horn" S. 20 | AB7: construction, wind turbne, 3.2 MW, DDSG, DDPMSG, DFIG, onshore_kW | AC7: production, PV, slanted-roof installation, 3kWp, CdTe_kW
A8: solar_thermal_FPC | B8: 0 | C8: bus_th | D8: m² | E8: 0 | F8: 0 | G8: 0 | H8: 1000000000000 | I8: 0 | J8: empty | K8: 1 | L8: 11 | M8: 526 | N8: 20 | O8: 1000000000000 | P8: 1000000 | Q8: production, solar collector system, Cu flat plate collector, multiple dwelling, for combined system, investment_m2 | R8: 1 | S8: 1 | Y8: 0.5 kW/m² | Z8: invest: invest kosten + maintenance/leistung | AB8: construction, wind turbine, onshore_kW | AC8: construction, photovoltaic plant, 570kWp open ground, cryst_2021_kW
A9: solar_thermal_FPC_low | B9: 0 | C9: bus_th_low | D9: m² | E9: 0 | F9: 0 | G9: 0 | H9: 1000000000000 | I9: 0 | J9: empty | K9: 1 | L9: 11 | M9: 526 | N9: 20 | O9: 1000000000000 | P9: 1000000 | Q9: production, solar collector system, Cu flat plate collector, multiple dwelling, for combined system, investment_m2 | R9: 1 | S9: 1 | AC9: construction, photovoltaic plant, 570kWp open ground, CdTE_kW
A10: solar_thermal_FPC_high | B10: 0 | C10: bus_th_high | D10: m² | E10: 0 | F10: 0 | G10: 0 | H10: 1000000000000 | I10: 0 | J10: empty | K10: 1 | L10: 11 | M10: 526 | N10: 20 | O10: 1000000000000 | P10: 1000000 | Q10: production, solar collector system, Cu flat plate collector, multiple dwelling, for combined system, investment_m2 | R10: 1 | S10: 1 | AC10: construction, photovoltaic plant, 1.3MWp, open ground, cryst-Si_2021_kW
AC11: construction, photovoltaic plant, 1.3MWp open ground, CdTe_kW
A12: PV_og_existing | B12: 0 | C12: bus_el | D12: kWp | E12: 1 | F12: 1000 | G12: 0 | H12: 1000000000000 | I12: 0 | J12: empty | K12: 1 | L12: =0.025*M12 -> 0 | M12: 0 | N12: 3 | O12: 0 | P12: 1000 | Q12: empty | R12: =1/3 -> 0.33333333 | S12: 1 | T12: 0
A14: PV_og_25 | B14: 1 | C14: bus_el-re | D14: kWp | E14: 0 | F14: 0 | G14: 0 | H14: 2030 | I14: 0 | J14: empty | K14: 1 | L14: =$L$23 -> 10.7 | M14: 509 | N14: =$N$23 -> 20 | O14: 1000000 | P14: =$P$23 -> 1000000 | Q14: PV_og plant construction, 570kWp, multi-Si | R14: =1/570 -> 0.001754386 | S14: 1 | T14: 0 | Y14: source costs: Langfristszenarien, 750 kW plant | AB14: construction, wind turbine, 3MW, DDSG, onshore_kW | AC14: production, PV, facade installation, 3kWp, cryst_2021_kW_minus_facade_mat
A15: PV_og_30 | B15: 1 | C15: bus_el-re | D15: kWp | E15: 0 | F15: 0 | G15: 2030 | H15: 2035 | I15: 0 | J15: empty | K15: 1 | L15: =$L$23 -> 10.7 | M15: 430 | N15: =$N$23 -> 20 | O15: 1000000 | P15: =$P$23 -> 1000000 | Q15: PV_og plant construction, 570kWp, multi-Si | R15: =1/570 -> 0.001754386 | S15: 1 | T15: 0 | Y15: construction LCA is probably too pessimistic
A16: PV_og_35 | B16: 1 | C16: bus_el-re | D16: kWp | E16: 0 | F16: 0 | G16: 2035 | H16: 2040 | I16: 0 | J16: empty | K16: 1 | L16: =$L$23 -> 10.7 | M16: 392 | N16: =$N$23 -> 20 | O16: 1000000 | P16: =$P$23 -> 1000000 | Q16: PV_og plant construction, 570kWp, multi-Si | R16: =1/570 -> 0.001754386 | S16: 1 | T16: 0
A17: PV_og_40 | B17: 1 | C17: bus_el-re | D17: kWp | E17: 0 | F17: 0 | G17: 2040 | H17: 2045 | I17: 0 | J17: empty | K17: 1 | L17: =$L$23 -> 10.7 | M17: 369 | N17: =$N$23 -> 20 | O17: 1000000 | P17: =$P$23 -> 1000000 | Q17: PV_og plant construction, 570kWp, multi-Si | R17: =1/570 -> 0.001754386 | S17: 1 | T17: 0
A18: PV_og_45 | B18: 1 | C18: bus_el-re | D18: kWp | E18: 0 | F18: 0 | G18: 2045 | H18: 2050 | I18: 0 | J18: empty | K18: 1 | L18: =$L$23 -> 10.7 | M18: 356 | N18: =$N$23 -> 20 | O18: 1000000 | P18: =$P$23 -> 1000000 | Q18: PV_og plant construction, 570kWp, multi-Si | R18: =1/570 -> 0.001754386 | S18: 1 | T18: 0
A19: PV_og_50 | B19: 1 | C19: bus_el-re | D19: kWp | E19: 0 | F19: 0 | G19: 2050 | H19: 2055 | I19: 0 | J19: empty | K19: 1 | L19: =$L$23 -> 10.7 | M19: 347 | N19: =$N$23 -> 20 | O19: 1000000 | P19: =$P$23 -> 1000000 | Q19: PV_og plant construction, 570kWp, multi-Si | R19: =1/570 -> 0.001754386 | S19: 1 | T19: 0
A20: PV_og_55 | B20: 1 | C20: bus_el-re | D20: kWp | E20: 0 | F20: 0 | G20: 2055 | H20: 2060 | I20: 0 | J20: empty | K20: 1 | L20: =$L$23 -> 10.7 | M20: 347 | N20: =$N$23 -> 20 | O20: 1000000 | P20: =$P$23 -> 1000000 | Q20: PV_og plant construction, 570kWp, multi-Si | R20: =1/570 -> 0.001754386 | S20: 1 | T20: 0
A21: PV_og_60 | B21: 1 | C21: bus_el-re | D21: kWp | E21: 0 | F21: 0 | G21: 2060 | H21: 2065 | I21: 0 | J21: empty | K21: 1 | L21: =$L$23 -> 10.7 | M21: 347 | N21: =$N$23 -> 20 | O21: 1000000 | P21: =$P$23 -> 1000000 | Q21: PV_og plant construction, 570kWp, multi-Si | R21: =1/570 -> 0.001754386 | S21: 1 | T21: 0
A22: PV_og_65 | B22: 1 | C22: bus_el-re | D22: kWp | E22: 0 | F22: 0 | G22: 2065 | H22: 2070 | I22: 0 | J22: empty | K22: 1 | L22: =$L$23 -> 10.7 | M22: 347 | N22: =$N$23 -> 20 | O22: 1000000 | P22: =$P$23 -> 1000000 | Q22: PV_og plant construction, 570kWp, multi-Si | R22: =1/570 -> 0.001754386 | S22: 1 | T22: 0
A23: PV_og_70 | B23: 1 | C23: bus_el-re | D23: kWp | E23: 0 | F23: 0 | G23: 2070 | H23: 2075 | I23: 0 | J23: empty | K23: 1 | L23: 10.7 | M23: 347 | N23: 20 | O23: 1000000 | P23: 1000000 | Q23: PV_og plant construction, 570kWp, multi-Si | R23: =1/570 -> 0.001754386 | S23: 1 | T23: 0
A25: windon_25 | B25: 1 | C25: bus_el-re | D25: kW | E25: 0 | F25: 0 | G25: 0 | H25: 2030 | I25: 0 | J25: =IF(Q25=AB25,AA25,"empty") -> empty | K25: 1 | L25: =$L$34 -> 20.6 | M25: 1453 | N25: =$N$34 -> 20 | O25: =$P$34 -> 50000 | P25: =$P$34 -> 50000 | Q25: market for wind turbine, 4.5MW, onshore | R25: =1/4500 -> 0.00022222222 | S25: 1 | U25: V126/3300 | V25: 150 | W25: 3300 | Y25: source costs: Langfristszenarien, 150m hub height, 280 W/m² | AA25: electricity, wind, max 1MW turbine, onshore, variable_kWh | AB25: construction, wind, max 1MW turbine, onshore, investment_kW | AC25: procution, PV, flat-roof installation, 156kWp, cryst_2021_kW
A26: windon_30 | B26: 1 | C26: bus_el-re | D26: kW | E26: 0 | F26: 0 | G26: 2030 | H26: 2035 | I26: 0 | J26: empty | K26: 1 | L26: =$L$34 -> 20.6 | M26: 1387 | N26: =$N$34 -> 20 | O26: =$P$34 -> 50000 | P26: =$P$34 -> 50000 | Q26: market for wind turbine, 4.5MW, onshore | R26: =1/4500 -> 0.00022222222 | S26: 1 | U26: V126/3300 | V26: 150 | W26: 3300 | Y26: construction LCA is probably too pessimistic
A27: windon_35 | B27: 1 | C27: bus_el-re | D27: kW | E27: 0 | F27: 0 | G27: 2035 | H27: 2040 | I27: 0 | J27: empty | K27: 1 | L27: =$L$34 -> 20.6 | M27: 1349 | N27: =$N$34 -> 20 | O27: =$P$34 -> 50000 | P27: =$P$34 -> 50000 | Q27: market for wind turbine, 4.5MW, onshore | R27: =1/4500 -> 0.00022222222 | S27: 1 | U27: V126/3300 | V27: 150 | W27: 3300
A28: windon_40 | B28: 1 | C28: bus_el-re | D28: kW | E28: 0 | F28: 0 | G28: 2040 | H28: 2045 | I28: 0 | J28: empty | K28: 1 | L28: =$L$34 -> 20.6 | M28: 1326 | N28: =$N$34 -> 20 | O28: =$P$34 -> 50000 | P28: =$P$34 -> 50000 | Q28: market for wind turbine, 4.5MW, onshore | R28: =1/4500 -> 0.00022222222 | S28: 1 | U28: V126/3300 | V28: 150 | W28: 3300
A29: windon_45 | B29: 1 | C29: bus_el-re | D29: kW | E29: 0 | F29: 0 | G29: 2045 | H29: 2050 | I29: 0 | J29: empty | K29: 1 | L29: =$L$34 -> 20.6 | M29: 1311 | N29: =$N$34 -> 20 | O29: =$P$34 -> 50000 | P29: =$P$34 -> 50000 | Q29: market for wind turbine, 4.5MW, onshore | R29: =1/4500 -> 0.00022222222 | S29: 1 | U29: V126/3300 | V29: 150 | W29: 3300
A30: windon_50 | B30: 1 | C30: bus_el-re | D30: kW | E30: 0 | F30: 0 | G30: 2050 | H30: 2055 | I30: 0 | J30: empty | K30: 1 | L30: =$L$34 -> 20.6 | M30: 1301 | N30: =$N$34 -> 20 | O30: =$P$34 -> 50000 | P30: =$P$34 -> 50000 | Q30: market for wind turbine, 4.5MW, onshore | R30: =1/4500 -> 0.00022222222 | S30: 1 | U30: V126/3300 | V30: 150 | W30: 3300
A31: windon_55 | B31: 1 | C31: bus_el-re | D31: kW | E31: 0 | F31: 0 | G31: 2055 | H31: 2060 | I31: 0 | J31: empty | K31: 1 | L31: =$L$34 -> 20.6 | M31: 1301 | N31: =$N$34 -> 20 | O31: =$P$34 -> 50000 | P31: =$P$34 -> 50000 | Q31: market for wind turbine, 4.5MW, onshore | R31: =1/4500 -> 0.00022222222 | S31: 1 | U31: V126/3300 | V31: 150 | W31: 3300
A32: windon_60 | B32: 1 | C32: bus_el-re | D32: kW | E32: 0 | F32: 0 | G32: 2060 | H32: 2065 | I32: 0 | J32: empty | K32: 1 | L32: =$L$34 -> 20.6 | M32: 1301 | N32: =$N$34 -> 20 | O32: =$P$34 -> 50000 | P32: =$P$34 -> 50000 | Q32: market for wind turbine, 4.5MW, onshore | R32: =1/4500 -> 0.00022222222 | S32: 1 | U32: V126/3300 | V32: 150 | W32: 3300
A33: windon_65 | B33: 1 | C33: bus_el-re | D33: kW | E33: 0 | F33: 0 | G33: 2065 | H33: 2070 | I33: 0 | J33: empty | K33: 1 | L33: =$L$34 -> 20.6 | M33: 1301 | N33: =$N$34 -> 20 | O33: =$P$34 -> 50000 | P33: =$P$34 -> 50000 | Q33: market for wind turbine, 4.5MW, onshore | R33: =1/4500 -> 0.00022222222 | S33: 1 | U33: V126/3300 | V33: 150 | W33: 3300
A34: windon_70 | B34: 1 | C34: bus_el-re | D34: kW | E34: 0 | F34: 0 | G34: 2070 | H34: 2075 | I34: 0 | J34: empty | K34: 1 | L34: 20.6 | M34: 1301 | N34: 20 | O34: =$P$34 -> 50000 | P34: 50000 | Q34: market for wind turbine, 4.5MW, onshore | R34: =1/4500 -> 0.00022222222 | S34: 1 | U34: V126/3300 | V34: 150 | W34: 3300
A36: windoff_25 | B36: 1 | C36: bus_el-over | D36: kW | E36: 0 | F36: 0 | G36: 0 | H36: 2030 | I36: 0 | J36: empty | K36: 1 | L36: =$L$45 -> 58.9 | M36: 3466 | N36: =$N$45 -> 20 | O36: 1000000 | P36: =$P$45 -> 1000000 | Q36: wind turbine offshore, 2MW | R36: =1/2000 -> 0.0005 | S36: 1 | U36: V164/8000 | V36: 150 | W36: 8000 | Y36: source costs: Langfristszenarien, 160m hub height, 350 W/m²
A37: windoff_30 | B37: 1 | C37: bus_el-over | D37: kW | E37: 0 | F37: 0 | G37: 2030 | H37: 2035 | I37: 0 | J37: empty | K37: 1 | L37: =$L$45 -> 58.9 | M37: 3438 | N37: =$N$45 -> 20 | O37: 1000000 | P37: =$P$45 -> 1000000 | Q37: wind turbine offshore, 2MW | R37: =1/2000 -> 0.0005 | S37: 1 | U37: V164/8000 | V37: 150 | W37: 8000 | Y37: attention: actually, price is also dependent on water depth and distance to next coast
A38: windoff_35 | B38: 1 | C38: bus_el-over | D38: kW | E38: 0 | F38: 0 | G38: 2035 | H38: 2040 | I38: 0 | J38: empty | K38: 1 | L38: =$L$45 -> 58.9 | M38: 3394 | N38: =$N$45 -> 20 | O38: 1000000 | P38: =$P$45 -> 1000000 | Q38: wind turbine offshore, 2MW | R38: =1/2000 -> 0.0005 | S38: 1 | U38: V164/8000 | V38: 150 | W38: 8000
A39: windoff_40 | B39: 1 | C39: bus_el-over | D39: kW | E39: 0 | F39: 0 | G39: 2040 | H39: 2045 | I39: 0 | J39: empty | K39: 1 | L39: =$L$45 -> 58.9 | M39: 3348 | N39: =$N$45 -> 20 | O39: 1000000 | P39: =$P$45 -> 1000000 | Q39: wind turbine offshore, 2MW | R39: =1/2000 -> 0.0005 | S39: 1 | U39: V164/8000 | V39: 150 | W39: 8000
A40: windoff_45 | B40: 1 | C40: bus_el-over | D40: kW | E40: 0 | F40: 0 | G40: 2045 | H40: 2050 | I40: 0 | J40: empty | K40: 1 | L40: =$L$45 -> 58.9 | M40: 3309 | N40: =$N$45 -> 20 | O40: 1000000 | P40: =$P$45 -> 1000000 | Q40: wind turbine offshore, 2MW | R40: =1/2000 -> 0.0005 | S40: 1 | U40: V164/8000 | V40: 150 | W40: 8000
A41: windoff_50 | B41: 1 | C41: bus_el-over | D41: kW | E41: 0 | F41: 0 | G41: 2050 | H41: 2055 | I41: 0 | J41: empty | K41: 1 | L41: =$L$45 -> 58.9 | M41: 3271 | N41: =$N$45 -> 20 | O41: 1000000 | P41: =$P$45 -> 1000000 | Q41: wind turbine offshore, 2MW | R41: =1/2000 -> 0.0005 | S41: 1 | U41: V164/8000 | V41: 150 | W41: 8000
A42: windoff_55 | B42: 1 | C42: bus_el-over | D42: kW | E42: 0 | F42: 0 | G42: 2055 | H42: 2060 | I42: 0 | J42: empty | K42: 1 | L42: =$L$45 -> 58.9 | M42: 3271 | N42: =$N$45 -> 20 | O42: 1000000 | P42: =$P$45 -> 1000000 | Q42: wind turbine offshore, 2MW | R42: =1/2000 -> 0.0005 | S42: 1 | U42: V164/8000 | V42: 150 | W42: 8000
A43: windoff_60 | B43: 1 | C43: bus_el-over | D43: kW | E43: 0 | F43: 0 | G43: 2060 | H43: 2065 | I43: 0 | J43: empty | K43: 1 | L43: =$L$45 -> 58.9 | M43: 3271 | N43: =$N$45 -> 20 | O43: 1000000 | P43: =$P$45 -> 1000000 | Q43: wind turbine offshore, 2MW | R43: =1/2000 -> 0.0005 | S43: 1 | U43: V164/8000 | V43: 150 | W43: 8000
A44: windoff_65 | B44: 1 | C44: bus_el-over | D44: kW | E44: 0 | F44: 0 | G44: 2065 | H44: 2070 | I44: 0 | J44: empty | K44: 1 | L44: =$L$45 -> 58.9 | M44: 3271 | N44: =$N$45 -> 20 | O44: 1000000 | P44: =$P$45 -> 1000000 | Q44: wind turbine offshore, 2MW | R44: =1/2000 -> 0.0005 | S44: 1 | U44: V164/8000 | V44: 150 | W44: 8000
...

Sheet storages
A1: label | B1: active | C1: bus | D1: unit | E1: initial_existance | F1: initially_installed_capacity | G1: year_of_availability | H1: end_of_availability | I1: balanced | J1: capacity loss | K1: efficiency inflow | L1: efficiency outflow | M1: initial capacity | N1: capacity min | O1: capacity max | P1: invest_relation_input_capacity | Q1: invest_relation_output_capacity | R1: variable_input_costs | S1: variable_output_costs | T1: max_capacity_invest | U1: max_total_capacity | V1: inv1 | W1: inv1_conversion | X1: om | Y1: invest | Z1: lifetime | AA1: comment
A2: batt_VRF | B2: 0 | C2: bus_el | D2: kWh | E2: 0 | F2: 0 | G2: 0 | H2: 1000000 | I2: 0 | J2: 0.02 | K2: 0.965 | L2: =0.83*K2 -> 0.80095 | M2: 0 | N2: 0.15 | O2: 0.85 | P2: 0.25 | Q2: 0.25 | R2: 0 | S2: 0 | T2: 1000000 | U2: 1000000 | V2: production, stationary battery, VRF (19.4 Wh effective per kg), investment_kWh | W2: 1 | X2: 25 | Y2: 833 | Z2: 20
A3: heat_storage_high | B3: 0 | C3: bus_th_high | D3: kWh | E3: 0 | F3: 0 | G3: 0 | H3: 1000000 | I3: 0 | J3: 0.00015850428 | K3: 1 | L3: =0.81^0.5 -> 0.9 | M3: 0 | N3: 0 | O3: 1 | P3: =1/72 -> 0.013888889 | Q3: =1/72 -> 0.013888889 | R3: 0 | S3: 0 | T3: 1000000 | U3: 1000000 | V3: production, heat storage, 2000l_unit | W3: =1/AA3 -> 0.01076555 | X3: 0 | Y3: 41 | Z3: 30 | AA3: =2000*(95-55)*(4.18/1000/3.6) -> 92.888889
A4: heat_storage_low | B4: 0 | C4: bus_th_low | D4: kWh | E4: 0 | F4: 0 | G4: 0 | H4: 1000000 | I4: 0 | J4: 0.00011991014 | K4: 1 | L4: =0.81^0.5 -> 0.9 | M4: 0 | N4: 0 | O4: 1 | P4: =1/72 -> 0.013888889 | Q4: =1/72 -> 0.013888889 | R4: 0 | S4: 0 | T4: 1000000 | U4: 1000000 | V4: production, heat storage, 2000l_unit | W4: =1/AA4 -> 0.0078294911 | X4: 0 | Y4: 29.867537 | Z4: 30 | AA4: =2000*(95-40)*(4.18/1000/3.6) -> 127.72222
A5: heat_storage | B5: 0 | C5: bus_th | D5: kWh | E5: 0 | F5: 0 | G5: 0 | H5: 1000000 | I5: 0 | J5: 0.00015850428 | K5: 1 | L5: =0.81^0.5 -> 0.9 | M5: 0 | N5: 0 | O5: 1 | P5: =1/72 -> 0.013888889 | Q5: =1/72 -> 0.013888889 | R5: 0 | S5: 0 | T5: 1000000 | U5: 1000000 | V5: production, heat storage, 2000l_unit | W5: =1/AA5 -> 0.01076555 | X5: 0 | Y5: 41 | Z5: 30 | AA5: =2000*(95-55)*(4.18/1000/3.6) -> 92.888889
A6: hydrogen_storage | B6: 0 | C6: bus_hydrogen | D6: kg | E6: 0 | F6: 0 | G6: 0 | H6: 1000000 | I6: 0 | J6: 0 | K6: 1 | L6: 1 | M6: 0 | N6: 0 | O6: 1 | P6: 0.2 | Q6: 0.2 | R6: 0 | S6: 0 | T6: 1000000 | U6: 1000000 | V6: storage production, 10'000 l, investment_unit | W6: =1/120 -> 0.0083333333 | X6: 1 | Y6: 500 | Z6: 25 | AA6: =3/1000*10000 -> 30
A8: h2_reservoir | B8: 1 | C8: bus_hydrogen_proxy | D8: kg | E8: 0 | F8: 0 | G8: 0 | H8: 1000000 | I8: 0 | J8: 0 | K8: 1 | L8: 1 | M8: 0 | N8: 0 | O8: 0.8 | P8: 0.25 | Q8: 0.25 | R8: 0 | S8: 0 | T8: 1000000 | U8: 1000000 | V8: storage production, 10'000 l | W8: =1/(10*0.0899)/30 -> 0.037078235 | X8: =0.03*Y8 -> 30 | Y8: 1000 | Z8: 30 | AA8: actually, exponential electricity demand for compression is necessary
A10: batt_LFP | B10: 1 | C10: bus_el-stor | D10: kWh | E10: 0 | F10: 0 | G10: 0 | H10: 1000000 | I10: 0 | J10: =0.01/24 -> 0.00041666667 | K10: 0.96 | L10: 0.96 | M10: 0 | N10: 0 | O10: 0.8 | P10: 0.5 | Q10: 3 | R10: 0 | S10: 0 | T10: 1000000 | U10: 1000000 | V10: market for battery cell, Li-ion, LFP | W10: =1/0.159 -> 6.2893082 | X10: =0.03*Y10 -> 15 | Y10: 500 | Z10: 15 | AA10: taken from Kost2024

Sheet converters_in
A1: label | B1: active | C1: unit | D1: initial_existance | E1: initially_installed_capacity | F1: year_of_availability | G1: end_of_availability | H1: from1 | I1: conversion_factor_f1 | J1: var_from1_costs | K1: to1 | L1: conversion_factor_t1 | M1: var_to1_costs | N1: var_env1 | O1: var_env1_conversion | P1: to2 | Q1: conversion_factor_t2 | R1: var_env2 | S1: var_env2_conversion | T1: om | U1: invest | V1: invest_kWel | W1: lifetime | X1: max_capacity_invest | Y1: max_total_capacity | Z1: inv1 | AA1: inv1_conversion | AB1: fuel_based | AD1: comment
A2: CHP_nat_gas_m_gas_turb | B2: 0 | C2: kWin | D2: 0 | E2: 0 | F2: 0 | G2: 100000 | H2: bus_nat_gas | I2: 1 | J2: 0 | K2: bus_el | L2: 0.29 | M2: 0 | N2: electricity, CHP, natural gas, burned in micro gas turbine, 345 kW, 100kWe, variable_kWh | O2: 1 | P2: bus_th | Q2: 0.46 | R2: heat, central or small-scale, CHP, natural gas, low pressure, burned in micro gas turbine, 345 kW, 100kWe - variable_MJ | S2: 3.6 | T2: =0.0035/L2 -> 0.012068966 | U2: =V2*L2 -> 431.23 | V2: 1487 | W2: 15 | X2: 100000 | Y2: 100000 | Z2: construction, CHP, micro gas turbine, 345 kW, 160 kWth, 100kWe, investment_kW | AA2: 1 | AB2: 1
A3: CHP_biometh_m_gas_turb | B3: 0 | C3: kWin | D3: 0 | E3: 0 | F3: 0 | G3: 100000 | H3: bus_biometh | I3: 1 | J3: 0 | K3: bus_el | L3: 0.29 | M3: 0 | N3: electricity, CHP, biomethane, low pressure burned in micro gas turbine 345 kW, 100kWe, variable_kWh | O3: 1 | P3: bus_th | Q3: 0.46 | R3: heat, central or small-scale, CHP, biomethane, low pressure burned in micro gas turbine, 345 kW, 100kWe, variable_MJ | S3: 3.6 | T3: =0.0069/L3 -> 0.023793103 | U3: =V3*L3 -> 455.59 | V3: 1571 | W3: 15 | X3: 100000 | Y3: 100000 | Z3: construction, CHP, micro gas turbine, 345 kW, 160 kWth, 100kWe, investment_kW | AA3: 1 | AB3: 1
A4: CHP_biometh_PEM_FC | B4: 0 | C4: kWin | D4: 0 | E4: 0 | F4: 0 | G4: 100000 | H4: bus_biometh | I4: 1 | J4: 0 | K4: bus_el | L4: 0.32 | M4: 0 | N4: electricity, CHP, biomethane, low pressure burned in polymer electrolyte membrane fuel cell 2kWe, future, variable_kWh | O4: 1 | P4: bus_th | Q4: 0.55 | R4: heat, central or small-scale, CHP, biomethane, low pressure burned in polymer electrolyte membrane fuel cell 2kWe, future, variable_MJ | S4: 3.6 | T4: 0 | U4: =V4*L4 -> 1532.8 | V4: 4790 | W4: 15 | X4: 100000 | Y4: 100000 | Z4: construction, CHP, fuel cell, polymer electrolyte membrane, 6.25kW, 2kWe, 3.44 kWth, future, investment_kW | AA4: 1 | AB4: 1
A5: CHP_biometh_SO_FC | B5: 0 | C5: kWin | D5: 0 | E5: 0 | F5: 0 | G5: 100000 | H5: bus_biometh | I5: 1 | J5: 0 | K5: bus_el | L5: 0.47 | M5: 0 | N5: electricity, CHP, biomethane, low pressure burned in solid oxide fuel cell 266 kW, 125kWe, future, variable_kWh | O5: 1 | P5: bus_th | Q5: 0.33 | R5: heat, central or small-scale, CHP, biomethane, low pressure burned in solid oxide fuel cell, 266 kW, 125kWe, future, variable_MJ | S5: 3.6 | T5: 0 | U5: =V5*L5 -> 864.8 | V5: 1840 | W5: 15 | X5: 100000 | Y5: 100000 | Z5: construction, CHP, fuel cell, solid oxide, 266 kW, 125kWe, future, investment_kW | AA5: 1 | AB5: 1
A6: CHP_biometh_SO_FC_mGT | B6: 0 | C6: kWin | D6: 0 | E6: 0 | F6: 0 | G6: 100000 | H6: bus_biometh | I6: 1 | J6: 0 | K6: bus_el | L6: 0.58 | M6: 0 | N6: electricity, CHP, biomethane, low pressure burned in solid oxide fuel cell, with micro gas turbine, 327 kW, 180kWe, future, variable_kWh | O6: 1 | P6: bus_th | Q6: 0.22 | R6: heat, central or small-scale, CHP, biomethane, low pressure burned in solid oxide fuel cell, with micro gas turbine, 327 kW, 180kWe, future, variable_MJ | S6: 3.6 | T6: =0.014/L6 -> 0.024137931 | U6: =V6*L6 -> 2181.38 | V6: 3761 | W6: 15 | X6: 100000 | Y6: 100000 | Z6: construction, CHP, fuel cell, solid oxide, with micro gas turbine, 327kW, 180kWe, 92kWth, future, investment_kW | AA6: 1 | AB6: 1
A7: CHP_2000_w_chips | B7: 0 | C7: kWin | D7: 0 | E7: 0 | F7: 0 | G7: 100000 | H7: bus_w_chips | I7: 1 | J7: 0 | K7: bus_el | L7: =1/(0.9*0.8*18.9/3.6) -> 0.26455026 | M7: 0.034 | N7: electricity, CHP, wood chips, 2000 kW, 1200 kWth, 530 kWel, variable_kWh | O7: 1 | P7: bus_th | Q7: =(111.3/49)/(0.9*0.8*18.9/3.6) -> 0.60090703 | R7: heat, district or industrial, CHP, wood chips, 2000 kW, 1200 kWth, 530 kWel, variable_kWh | S7: 1 | T7: 0 | U7: =V7*L7 -> 1239.9471 | V7: 4687 | W7: 15 | X7: 100000 | Y7: 100000 | Z7: construction, CHP, wood chips, 2000 kW, investment_kW | AA7: 1 | AB7: 1
A8: CHP_6667_w_chips | B8: 0 | C8: kWin | D8: 0 | E8: 0 | F8: 0 | G8: 100000 | H8: bus_w_chips | I8: 1 | J8: 0 | K8: bus_el | L8: 0.15 | M8: 0.034 | N8: electricity, CHP, wood chips, wet, 6667 kW, state-of-the-art 2014, variable_kWh | O8: 1 | P8: bus_th | Q8: 0.45 | R8: heat, district or industrial, CHP, wood chips, wet, 6667 kW, state-of-the-art 2014, variable_MJ | S8: 3.6 | T8: 0 | U8: =V8*L8 -> 703.05 | V8: 4687 | W8: 15 | X8: 100000 | Y8: 100000 | Z8: construction, CHP, wood chips, 6667 kW, state-of-the-art 2014, investment_kW | AA8: 1 | AB8: 1
A9: electrolyzer | B9: 0 | C9: kWin | D9: 0 | E9: 0 | F9: 0 | G9: 100000 | H9: bus_el | I9: 1 | J9: 0 | K9: bus_hydrogen | L9: =0.7/33.3 -> 0.021021021 | M9: 0 | N9: empty | O9: 1 | P9: bus_oxygen | Q9: =L9/2*18/2 -> 0.094594595 | R9: empty | S9: 1 | T9: 0 | U9: 1 | W9: 15 | X9: 100000 | Y9: 100000 | Z9: construction, CHP, fuel cell, polymer electrolyte membrane, 6.25kW, 2kWe, 3.44 kWth, future, investment_kW | AA9: 1 | AB9: 0
A10: hydrogen_fuel_cell | B10: 0 | C10: kg | D10: 0 | E10: 0 | F10: 0 | G10: 100000 | H10: bus_hydrogen | I10: 1 | J10: 0 | K10: bus_el | L10: =0.5*33.3 -> 16.65 | M10: 0 | N10: empty | O10: 1 | T10: 0 | U10: 1 | W10: 15 | X10: 100000 | Y10: 100000 | Z10: construction, CHP, fuel cell, polymer electrolyte membrane, 6.25kW, 2kWe, 3.44 kWth, future, investment_kW | AA10: 33.3 | AB10: 0
A12: boiler_nat_gas | B12: 0 | C12: kWth | D12: 0 | E12: 0 | F12: 0 | G12: 100000 | H12: bus_nat_gas | I12: 1 | J12: 0 | K12: bus_co2_emission | L12: 0.20031363 | M12: 0 | N12: empty | O12: 1 | P12: bus_th_households | Q12: 1.02 | R12: empty | S12: 1 | T12: =0.03*U12 -> 6.579 | U12: =215*Q12 -> 219.3 | V12: 0 | W12: 20 | X12: 100000 | Y12: 100000 | Z12: gas boiler production, 10kWgas | AA12: =1/10 -> 0.1 | AB12: 1 | AD12: reference: KEA Technikkatalog
A15: smre_proxy_o1 | B15: 1 | C15: kg/h | D15: 0 | E15: 0 | F15: 0 | G15: 100000 | H15: bus_smre | I15: 1 | J15: 0 | K15: bus_smr-exhaust | L15: =2751.64/89.93 -> 30.597576 | M15: 0 | N15: empty | O15: 1 | P15: bus_smre_po1 | Q15: 1 | R15: empty | S15: 1 | T15: 0 | U15: 0 | V15: 0 | W15: 100 | X15: 1000 | Y15: 1000 | Z15: empty | AA15: 1 | AB15: 1
A16: smre_proxy_o2 | B16: 1 | C16: kg/h | D16: 0 | E16: 0 | F16: 0 | G16: 100000 | H16: bus_smre_po1 | I16: 1 | J16: 0 | K16: bus_steam7,5bar | L16: =(440.46*1/1.3)/89.93 -> 3.7675457 | M16: 0 | N16: empty | O16: 1 | P16: bus_hydrogen | Q16: 1 | R16: empty | S16: 1 | T16: 0 | U16: 0 | V16: 0 | W16: 100 | X16: 1000 | Y16: 1000 | Z16: empty | AA16: 1 | AB16: 1
A18: smr_proxy_o1 | B18: 1 | C18: kg/h | D18: 0 | E18: 0 | F18: 2025 | G18: 2030 | H18: bus_smr_pi2 | I18: 1 | J18: 0 | K18: bus_smr-exhaust | L18: =2751.64/89.93 -> 30.597576 | M18: 0 | N18: empty | O18: 1 | P18: bus_smr_po1 | Q18: 1 | R18: empty | S18: 1 | T18: 0 | U18: 0 | V18: 0 | W18: 100 | X18: 1000 | Y18: 1000 | Z18: empty | AA18: 1 | AB18: 1
A19: steam_methane_reformer_25 | B19: 1 | C19: kg/h | D19: 0 | E19: 0 | F19: 2025 | G19: 2030 | H19: bus_smr_po1 | I19: 1 | J19: 0 | K19: bus_steam7,5bar | L19: =(440.46*1/1.3)/89.93 -> 3.7675457 | M19: 0 | N19: empty | O19: 1 | P19: bus_hydrogen | Q19: 1 | R19: empty | S19: 1 | T19: =$T$28 -> 805 | U19: 29667 | V19: 0 | W19: =$W$28 -> 25 | X19: 1000 | Y19: =$Y$28 -> 1000 | Z19: SMR_cons_2025 | AA19: =1/9000.9 -> 0.0001111 | AB19: 1
A20: steam_methane_reformer_30 | B20: 1 | C20: kg/h | D20: 0 | E20: 0 | F20: 2030 | G20: 2035 | H20: bus_smr_po1 | I20: 1 | J20: 0 | K20: bus_steam7,5bar | L20: =(440.46*1/1.3)/89.93 -> 3.7675457 | M20: 0 | N20: empty | O20: 1 | P20: bus_hydrogen | Q20: 1 | R20: empty | S20: 1 | T20: =$T$28 -> 805 | U20: 28183 | V20: 0 | W20: =$W$28 -> 25 | X20: 1000 | Y20: =$Y$28 -> 1000 | Z20: SMR_cons_2030 | AA20: =1/9000.9 -> 0.0001111 | AB20: 1
A21: steam_methane_reformer_35 | B21: 1 | C21: kg/h | D21: 0 | E21: 0 | F21: 2035 | G21: 2040 | H21: bus_smr_po1 | I21: 1 | J21: 0 | K21: bus_steam7,5bar | L21: =(440.46*1/1.3)/89.93 -> 3.7675457 | M21: 0 | N21: empty | O21: 1 | P21: bus_hydrogen | Q21: 1 | R21: empty | S21: 1 | T21: =$T$28 -> 805 | U21: 26774 | V21: 0 | W21: =$W$28 -> 25 | X21: 1000 | Y21: =$Y$28 -> 1000 | Z21: SMR_cons_2035 | AA21: =1/9000.9 -> 0.0001111 | AB21: 1
A22: steam_methane_reformer_40 | B22: 1 | C22: kg/h | D22: 0 | E22: 0 | F22: 2040 | G22: 2045 | H22: bus_smr_po1 | I22: 1 | J22: 0 | K22: bus_steam7,5bar | L22: =(440.46*1/1.3)/89.93 -> 3.7675457 | M22: 0 | N22: empty | O22: 1 | P22: bus_hydrogen | Q22: 1 | R22: empty | S22: 1 | T22: =$T$28 -> 805 | U22: 25435 | V22: 0 | W22: =$W$28 -> 25 | X22: 1000 | Y22: =$Y$28 -> 1000 | Z22: SMR_cons_2040 | AA22: =1/9000.9 -> 0.0001111 | AB22: 1
A23: steam_methane_reformer_45 | B23: 1 | C23: kg/h | D23: 0 | E23: 0 | F23: 2045 | G23: 2050 | H23: bus_smr_po1 | I23: 1 | J23: 0 | K23: bus_steam7,5bar | L23: =(440.46*1/1.3)/89.93 -> 3.7675457 | M23: 0 | N23: empty | O23: 1 | P23: bus_hydrogen | Q23: 1 | R23: empty | S23: 1 | T23: =$T$28 -> 805 | U23: 24164 | V23: 0 | W23: =$W$28 -> 25 | X23: 1000 | Y23: =$Y$28 -> 1000 | Z23: SMR_cons_2045 | AA23: =1/9000.9 -> 0.0001111 | AB23: 1
A24: steam_methane_reformer_50 | B24: 1 | C24: kg/h | D24: 0 | E24: 0 | F24: 2050 | G24: 2055 | H24: bus_smr_po1 | I24: 1 | J24: 0 | K24: bus_steam7,5bar | L24: =(440.46*1/1.3)/89.93 -> 3.7675457 | M24: 0 | N24: empty | O24: 1 | P24: bus_hydrogen | Q24: 1 | R24: empty | S24: 1 | T24: =$T$28 -> 805 | U24: 24164 | V24: 0 | W24: =$W$28 -> 25 | X24: 1000 | Y24: =$Y$28 -> 1000 | Z24: SMR_cons_2045 | AA24: =1/9000.9 -> 0.0001111 | AB24: 1
A25: steam_methane_reformer_55 | B25: 1 | C25: kg/h | D25: 0 | E25: 0 | F25: 2055 | G25: 2060 | H25: bus_smr_po1 | I25: 1 | J25: 0 | K25: bus_steam7,5bar | L25: =(440.46*1/1.3)/89.93 -> 3.7675457 | M25: 0 | N25: empty | O25: 1 | P25: bus_hydrogen | Q25: 1 | R25: empty | S25: 1 | T25: =$T$28 -> 805 | U25: 24164 | V25: 0 | W25: =$W$28 -> 25 | X25: 1000 | Y25: =$Y$28 -> 1000 | Z25: SMR_cons_2045 | AA25: =1/9000.9 -> 0.0001111 | AB25: 1
A26: steam_methane_reformer_60 | B26: 1 | C26: kg/h | D26: 0 | E26: 0 | F26: 2060 | G26: 2065 | H26: bus_smr_po1 | I26: 1 | J26: 0 | K26: bus_steam7,5bar | L26: =(440.46*1/1.3)/89.93 -> 3.7675457 | M26: 0 | N26: empty | O26: 1 | P26: bus_hydrogen | Q26: 1 | R26: empty | S26: 1 | T26: =$T$28 -> 805 | U26: 24164 | V26: 0 | W26: =$W$28 -> 25 | X26: 1000 | Y26: =$Y$28 -> 1000 | Z26: SMR_cons_2045 | AA26: =1/9000.9 -> 0.0001111 | AB26: 1
A27: steam_methane_reformer_65 | B27: 1 | C27: kg/h | D27: 0 | E27: 0 | F27: 2065 | G27: 2070 | H27: bus_smr_po1 | I27: 1 | J27: 0 | K27: bus_steam7,5bar | L27: =(440.46*1/1.3)/89.93 -> 3.7675457 | M27: 0 | N27: empty | O27: 1 | P27: bus_hydrogen | Q27: 1 | R27: empty | S27: 1 | T27: =$T$28 -> 805 | U27: 24164 | V27: 0 | W27: =$W$28 -> 25 | X27: 1000 | Y27: =$Y$28 -> 1000 | Z27: SMR_cons_2045 | AA27: =1/9000.9 -> 0.0001111 | AB27: 1
A28: steam_methane_reformer_70 | B28: 1 | C28: kg/h | D28: 0 | E28: 0 | F28: 2070 | G28: 2075 | H28: bus_smr_po1 | I28: 1 | J28: 0 | K28: bus_steam7,5bar | L28: =(440.46*1/1.3)/89.93 -> 3.7675457 | M28: 0 | N28: empty | O28: 1 | P28: bus_hydrogen | Q28: 1 | R28: empty | S28: 1 | T28: 805 | U28: 24164 | V28: 0 | W28: 25 | X28: 1000 | Y28: 1000 | Z28: SMR_cons_2045 | AA28: =1/9000.9 -> 0.0001111 | AB28: 1 | AD28: om actually 3% per year of invest costs
A30: smr_refurbish_25 | B30: 1 | C30: kg/h | D30: 0 | E30: 0 | F30: 2025 | G30: 2030 | H30: bus_smr_po1 | I30: 1 | J30: 0 | K30: bus_steam7,5bar | L30: =(440.46*1/1.3)/89.93 -> 3.7675457 | M30: 0 | N30: empty | O30: 1 | P30: bus_hydrogen | Q30: 1 | R30: empty | S30: 1 | T30: =$T$39 -> 805 | U30: =29667/5 -> 5933.4 | V30: 0 | W30: =$W$39 -> 5 | X30: 0 | Y30: =$Y$39 -> 1000 | Z30: empty | AA30: =1/9000.9 -> 0.0001111 | AB30: 1
A31: smr_refurbish_30 | B31: 1 | C31: kg/h | D31: 0 | E31: 0 | F31: 2030 | G31: 2035 | H31: bus_smr_po1 | I31: 1 | J31: 0 | K31: bus_steam7,5bar | L31: =(440.46*1/1.3)/89.93 -> 3.7675457 | M31: 0 | N31: empty | O31: 1 | P31: bus_hydrogen | Q31: 1 | R31: empty | S31: 1 | T31: =$T$39 -> 805 | U31: =28183/5 -> 5636.6 | V31: 0 | W31: =$W$39 -> 5 | X31: 1000 | Y31: =$Y$39 -> 1000 | Z31: empty | AA31: =1/9000.9 -> 0.0001111 | AB31: 1
A32: smr_refurbish_35 | B32: 1 | C32: kg/h | D32: 0 | E32: 0 | F32: 2035 | G32: 2040 | H32: bus_smr_po1 | I32: 1 | J32: 0 | K32: bus_steam7,5bar | L32: =(440.46*1/1.3)/89.93 -> 3.7675457 | M32: 0 | N32: empty | O32: 1 | P32: bus_hydrogen | Q32: 1 | R32: empty | S32: 1 | T32: =$T$39 -> 805 | U32: 26774 | V32: 0 | W32: =$W$39 -> 5 | X32: 0 | Y32: =$Y$39 -> 1000 | Z32: empty | AA32: =1/9000.9 -> 0.0001111 | AB32: 1
A33: smr_refurbish_40 | B33: 1 | C33: kg/h | D33: 0 | E33: 0 | F33: 2040 | G33: 2045 | H33: bus_smr_po1 | I33: 1 | J33: 0 | K33: bus_steam7,5bar | L33: =(440.46*1/1.3)/89.93 -> 3.7675457 | M33: 0 | N33: empty | O33: 1 | P33: bus_hydrogen | Q33: 1 | R33: empty | S33: 1 | T33: =$T$39 -> 805 | U33: 25435 | V33: 0 | W33: =$W$39 -> 5 | X33: 0 | Y33: =$Y$39 -> 1000 | Z33: empty | AA33: =1/9000.9 -> 0.0001111 | AB33: 1
A34: smr_refurbish_45 | B34: 1 | C34: kg/h | D34: 0 | E34: 0 | F34: 2045 | G34: 2050 | H34: bus_smr_po1 | I34: 1 | J34: 0 | K34: bus_steam7,5bar | L34: =(440.46*1/1.3)/89.93 -> 3.7675457 | M34: 0 | N34: empty | O34: 1 | P34: bus_hydrogen | Q34: 1 | R34: empty | S34: 1 | T34: =$T$39 -> 805 | U34: 24164 | V34: 0 | W34: =$W$39 -> 5 | X34: 0 | Y34: =$Y$39 -> 1000 | Z34: empty | AA34: =1/9000.9 -> 0.0001111 | AB34: 1
A35: smr_refurbish_50 | B35: 1 | C35: kg/h | D35: 0 | E35: 0 | F35: 2050 | G35: 2055 | H35: bus_smr_po1 | I35: 1 | J35: 0 | K35: bus_steam7,5bar | L35: =(440.46*1/1.3)/89.93 -> 3.7675457 | M35: 0 | N35: empty | O35: 1 | P35: bus_hydrogen | Q35: 1 | R35: empty | S35: 1 | T35: =$T$39 -> 805 | U35: 24164 | V35: 0 | W35: =$W$39 -> 5 | X35: 0 | Y35: =$Y$39 -> 1000 | Z35: empty | AA35: =1/9000.9 -> 0.0001111 | AB35: 1
A36: smr_refurbish_55 | B36: 1 | C36: kg/h | D36: 0 | E36: 0 | F36: 2055 | G36: 2060 | H36: bus_smr_po1 | I36: 1 | J36: 0 | K36: bus_steam7,5bar | L36: =(440.46*1/1.3)/89.93 -> 3.7675457 | M36: 0 | N36: empty | O36: 1 | P36: bus_hydrogen | Q36: 1 | R36: empty | S36: 1 | T36: =$T$39 -> 805 | U36: 24164 | V36: 0 | W36: =$W$39 -> 5 | X36: 0 | Y36: =$Y$39 -> 1000 | Z36: empty | AA36: =1/9000.9 -> 0.0001111 | AB36: 1
A37: smr_refurbish_60 | B37: 1 | C37: kg/h | D37: 0 | E37: 0 | F37: 2060 | G37: 2065 | H37: bus_smr_po1 | I37: 1 | J37: 0 | K37: bus_steam7,5bar | L37: =(440.46*1/1.3)/89.93 -> 3.7675457 | M37: 0 | N37: empty | O37: 1 | P37: bus_hydrogen | Q37: 1 | R37: empty | S37: 1 | T37: =$T$39 -> 805 | U37: 24164 | V37: 0 | W37: =$W$39 -> 5 | X37: 0 | Y37: =$Y$39 -> 1000 | Z37: empty | AA37: =1/9000.9 -> 0.0001111 | AB37: 1
A38: smr_refurbish_65 | B38: 1 | C38: kg/h | D38: 0 | E38: 0 | F38: 2065 | G38: 2070 | H38: bus_smr_po1 | I38: 1 | J38: 0 | K38: bus_steam7,5bar | L38: =(440.46*1/1.3)/89.93 -> 3.7675457 | M38: 0 | N38: empty | O38: 1 | P38: bus_hydrogen | Q38: 1 | R38: empty | S38: 1 | T38: =$T$39 -> 805 | U38: 24164 | V38: 0 | W38: =$W$39 -> 5 | X38: 0 | Y38: =$Y$39 -> 1000 | Z38: empty | AA38: =1/9000.9 -> 0.0001111 | AB38: 1
A39: smr_refurbish_70 | B39: 1 | C39: kg/h | D39: 0 | E39: 0 | F39: 2070 | G39: 2075 | H39: bus_smr_po1 | I39: 1 | J39: 0 | K39: bus_steam7,5bar | L39: =(440.46*1/1.3)/89.93 -> 3.7675457 | M39: 0 | N39: empty | O39: 1 | P39: bus_hydrogen | Q39: 1 | R39: empty | S39: 1 | T39: 805 | U39: 24164 | V39: 0 | W39: 5 | X39: 0 | Y39: 1000 | Z39: empty | AA39: =1/9000.9 -> 0.0001111 | AB39: 1 | AD39: om actually 3% per year of invest costs
A41: smr_exhaust-co2-ratio | B41: 1 | C41: kg/h | D41: 0 | E41: 0 | F41: 0 | G41: 100000 | H41: bus_smr-exhaust | I41: 1 | J41: 0 | K41: bus_co2_emission | L41: =815.99/2751.64 -> 0.29654679 | M41: 0 | N41: empty | O41: 1 | R41: empty | S41: 1 | T41: 0 | U41: 0 | V41: 0 | W41: 100 | X41: 100000 | Y41: 100000 | Z41: empty | AA41: 1 | AB41: 1
A43: ael_proxy_o1 | B43: 0 | C43: kg/h | D43: 0 | E43: 0 | F43: 0 | G43: 100000 | H43: bus_ael | I43: 1 | J43: 0 | K43: bus_oxygen | L43: =713.79/89.93 -> 7.9371734 | M43: 0 | N43: empty | O43: 1 | P43: bus_ael_po1 | Q43: =I43 -> 1 | R43: empty | S43: 1 | T43: 0 | U43: 0 | V43: 0 | W43: 100 | X43: 100000 | Y43: 100000 | Z43: empty | AA43: 1 | AB43: 0
A44: ael_proxy_o2 | B44: 0 | C44: kg/h | D44: 0 | E44: 0 | F44: 0 | G44: 100000 | H44: bus_ael_po1 | I44: 1 | J44: 0 | K44: bus_th60 | L44: =1145/89.93 -> 12.732125 | M44: 0 | N44: empty | O44: 1 | P44: bus_hydrogen | Q44: =I44 -> 1 | R44: empty | S44: 1 | T44: 0 | U44: 0 | V44: 0 | W44: 100 | X44: 100000 | Y44: 100000 | Z44: empty | AA44: 1 | AB44: 0
A46: pem_proxy_o1 | B46: 1 | C46: kg/h | D46: 0 | E46: 0 | F46: 0 | G46: 100000 | H46: bus_pem | I46: 1 | J46: 0 | K46: bus_oxygen | L46: =713.79/89.93 -> 7.9371734 | M46: 0 | N46: empty | O46: 1 | P46: bus_pem_po1 | Q46: =I46 -> 1 | R46: empty | S46: 1 | T46: 0 | U46: 0 | V46: 0 | W46: 100 | X46: 100000 | Y46: 100000 | Z46: empty | AA46: 1 | AB46: 0
A47: pem_proxy_o2 | B47: 1 | C47: kg/h | D47: 0 | E47: 0 | F47: 0 | G47: 100000 | H47: bus_pem_po1 | I47: 1 | J47: 0 | K47: bus_th60 | L47: =1325/89.93 -> 14.733682 | M47: 0 | N47: empty | O47: 1 | P47: bus_hydrogen | Q47: =I47 -> 1 | R47: empty | S47: 1 | T47: 0 | U47: 0 | V47: 0 | W47: 100 | X47: 100000 | Y47: 100000 | Z47: empty | AA47: 1 | AB47: 0
A49: aem_proxy_o1 | B49: 0 | C49: kg/h | D49: 0 | E49: 0 | F49: 0 | G49: 100000 | H49: bus_aem | I49: 1 | J49: 0 | K49: bus_oxygen | L49: =713.79/89.93 -> 7.9371734 | M49: 0 | N49: empty | O49: 1 | P49: bus_aem_po1 | Q49: =I49 -> 1 | R49: empty | S49: 1 | T49: 0 | U49: 0 | V49: 0 | W49: 100 | X49: 100000 | Y49: 100000 | Z49: empty | AA49: 1 | AB49: 0
...

Sheet converters_out
A1: label | B1: active | C1: unit | D1: initial_existance | E1: initially_installed_capacity | F1: year_of_availability | G1: end_of_availability | H1: from1 | I1: conversion_factor_f1 | J1: var_from1_costs | K1: from2 | L1: conversion_factor_f2 | M1: var_from2_costs | N1: to1 | O1: conversion_factor_t1 | P1: fixed_cop | Q1: var_to1_costs | R1: var_env1 | S1: var_env1_conversion | T1: om | U1: invest | V1: lifetime | W1: max_capacity_invest | X1: max_total_capacity | Y1: inv1 | Z1: inv1_conversion | AA1: fuel_based | AB1: T high | AC1: T low | AD1: quality factor_HP | AE1: comment
A2: boiler_nat_gas | B2: 0 | C2: kWth | D2: 0 | E2: 0 | F2: 0 | G2: 2100 | H2: bus_nat_gas | I2: 1 | J2: 0 | N2: bus_th | O2: 1.02 | P2: 0 | Q2: 0 | R2: heat, central or small-scale, natural gas, at boiler condensing modulating max 100kW, variable_MJ | S2: 3.6 | T2: 10.666667 | U2: 733 | V2: 20 | W2: 100000 | X2: 100000 | Y2: production, gas boiler, 10kW, investment_kW | Z2: 1 | AA2: 1
A3: heat_pump_a_w_high | B3: 0 | C3: kWth | D3: 0 | E3: 0 | F3: 0 | G3: 2100 | H3: bus_el | I3: 1 | J3: 0 | N3: bus_th | O3: 2.8 | P3: 1 | Q3: 0 | R3: heat, central or small-scale, air-water heat pump 10kW, variable_MJ | S3: 3.6 | T3: 21.428571 | U3: 708 | V3: 20 | W3: 100000 | X3: 100000 | Y3: production, air-water heat pump 10kW, investment_kW | Z3: 1 | AA3: 0
A4: heat_pump_a_w_low | B4: 0 | C4: kWth | D4: 0 | E4: 0 | F4: 0 | G4: 2100 | H4: bus_el | I4: 1 | J4: 0 | N4: bus_th_low | O4: 2.8 | P4: 1 | Q4: 0 | R4: heat, central or small-scale, air-water heat pump 10kW, variable_MJ | S4: 3.6 | T4: 21.428571 | U4: 708 | V4: 20 | W4: 100000 | X4: 100000 | Y4: production, air-water heat pump 10kW, investment_kW | Z4: 1 | AA4: 0
A5: heat_pump_b_w_high | B5: 0 | C5: kWth | D5: 0 | E5: 0 | F5: 0 | G5: 2100 | H5: bus_el | I5: 1 | J5: 0 | K5: bus_th_ambient | L5: =O5-I5 -> 2.9217391 | M5: 0 | N5: bus_th | O5: =(AB5+273)/(AB5-AC5)*AD5 -> 3.9217391 | P5: 0 | Q5: 0 | R5: heat, central or small-scale, brine-water heat pump 10kW, variable_MJ | S5: 3.6 | T5: 15 | U5: 776 | V5: 20 | W5: 100000 | X5: 100000 | Y5: production, brine-water heat pump 10kW, investment_kW | Z5: 1 | AA5: 0 | AB5: 55 | AC5: 9 | AD5: 0.55
A6: heat_pump_b_w_low | B6: 0 | C6: kWth | D6: 0 | E6: 0 | F6: 0 | G6: 2100 | H6: bus_el | I6: 1 | J6: 0 | K6: bus_th_ambient | L6: =O6-I6 -> 4.5532258 | M6: 0 | N6: bus_th_low | O6: =(AB6+273)/(AB6-AC6)*AD6 -> 5.5532258 | P6: 0 | Q6: 0 | R6: heat, central or small-scale, brine-water heat pump 10kW, variable_MJ | S6: 3.6 | T6: 15 | U6: 776 | V6: 20 | W6: 100000 | X6: 100000 | Y6: production, brine-water heat pump 10kW, investment_kW | Z6: 1 | AA6: 0 | AB6: 40 | AC6: 9 | AD6: 0.55
A7: furnace_25_w_pellet | B7: 0 | C7: kWth | D7: 0 | E7: 0 | F7: 0 | G7: 2100 | H7: bus_pellets | I7: 1 | J7: 0 | N7: bus_th | O7: 0.8 | P7: 0 | Q7: 0 | R7: heat, central or small-scale, wood pellet, at furnace 25kW, state-of-the-art 2014, variable_MJ | S7: 3.6 | T7: 20 | U7: 1333 | V7: 20 | W7: 100000 | X7: 100000 | Y7: production, furnace, pellets, 25kW, investment_kW | Z7: 1 | AA7: 1
A8: furnace_30_logs | B8: 0 | C8: kWth | D8: 0 | E8: 0 | F8: 0 | G8: 2100 | H8: bus_logs | I8: 1 | J8: 0 | N8: bus_th | O8: 0.75 | P8: 0 | Q8: 0 | R8: heat, central or small-scale, mixed logs, at furnace 30kW, state-of-the-art 2014, variable_MJ | S8: 3.6 | T8: 23.666667 | U8: 433 | V8: 15 | W8: 100000 | X8: 100000 | Y8: production, furnace, logs, 30kW, investment_kW | Z8: 1 | AA8: 1
A9: furnace_300_w_chips | B9: 0 | C9: kWth | D9: 0 | E9: 0 | F9: 0 | G9: 2100 | H9: bus_w_chips | I9: 1 | J9: 0 | N9: bus_th | O9: 0.8 | P9: 0 | Q9: 0 | R9: heat, district or industrial, wood chips, at furnace 300kWth, state-of-the-art 2014, variable_MJ | S9: 3.6 | T9: 38 | U9: 975 | V9: 20 | W9: 100000 | X9: 100000 | Y9: production, furnace, wood chips, with silo, 300kW, investment_kW | Z9: 1 | AA9: 1
A10: furnace_100_w_pellet | B10: 0 | C10: kWth | D10: 0 | E10: 0 | F10: 0 | G10: 2100 | H10: bus_pellets | I10: 1 | J10: 0 | N10: bus_th | O10: 0.8 | P10: 0 | Q10: 0 | R10: heat, central or small-scale, wood pellet, at furnace 300kW, state-of-the-art 2014, variable_MJ | S10: 3.6 | T10: 38 | U10: 975 | V10: 20 | W10: 100000 | X10: 100000 | Y10: production, furnace, wood pellet, 300kW, investment_kW | Z10: 1 | AA10: 1
A11: boiler_100_biometh | B11: 0 | C11: kWth | D11: 0 | E11: 0 | F11: 0 | G11: 2100 | H11: bus_biometh | I11: 1 | J11: 0 | N11: bus_th | O11: 1.02 | P11: 0 | Q11: 0 | R11: heat, central or small-scale, biomethane, at boiler condensing modulating max 100kW, variable_MJ | S11: 3.6 | T11: 10.666667 | U11: 733 | V11: 20 | W11: 100000 | X11: 100000 | Y11: production, gas boiler, 10kW, investment_kW | Z11: 1 | AA11: 1
A12: heating_unit | B12: 0 | C12: kWth | D12: 0 | E12: 0 | F12: 0 | G12: 2100 | H12: bus_el | I12: 1 | J12: 0 | N12: bus_th | O12: 1 | P12: 0 | Q12: 0 | R12: empty | S12: 1 | T12: 0 | U12: 36.8 | V12: 20 | W12: 100000 | X12: 100000 | Y12: production, auxiliary heating unit, electric, 5kW, investment_kW | Z12: 1 | AA12: 0
A13: converter_high_low | B13: 0 | C13: kWth | D13: 0 | E13: 0 | F13: 0 | G13: 2100 | H13: bus_th_high | I13: 1 | J13: 0 | N13: bus_th_low | O13: 1 | P13: 0 | Q13: 0 | R13: empty | S13: 1 | T13: 0 | U13: 0 | V13: 20 | W13: 100000 | X13: 100000 | Y13: empty | Z13: 1 | AA13: 0
A14: hydrogen_fuel_cell | B14: 0 | C14: kWel | D14: 0 | E14: 0 | F14: 0 | G14: 2100 | H14: bus_hydrogen | I14: 1 | J14: 0 | N14: bus_el | O14: =0.5*33.3 -> 16.65 | P14: 0 | Q14: 0 | R14: empty | S14: 1 | T14: 0 | U14: 1 | V14: 15 | W14: 100000 | X14: 100000 | Y14: construction, CHP, fuel cell, polymer electrolyte membrane, 6.25kW, 2kWe, 3.44 kWth, future, investment_kW | Z14: 3.125 | AA14: 0
A16: heat_pump_a_w | B16: 0 | C16: kWth | D16: 0 | E16: 0 | F16: 0 | G16: 100000 | H16: bus_el | I16: 1 | J16: 0 | N16: bus_th_households | O16: 2.8 | P16: 0 | Q16: 0 | R16: heat production, air-water heat pump R134a | S16: 3.6 | T16: =0.02*U16 -> 10.714286 | U16: =1500/O16 -> 535.71429 | V16: 20 | W16: 100000 | X16: 100000 | Y16: production, market for heat pump, brine-water, 10kW | Z16: =1/10 -> 0.1 | AA16: 0 | AE16: ref economic: KEA Technikkatalog; ref LCA: BRINE-WATER heat pump; especially var_env1 assumptions probably too pessimistic (cooling medium: R134a)
A19: smr_proxy_i1 | B19: 1 | C19: kg/h | D19: 0 | E19: 0 | F19: 0 | G19: 2100 | H19: bus_el | I19: 1 | J19: 0 | K19: bus_water_deionized | L19: =972.54/12.9 -> 75.390698 | M19: 0 | N19: bus_smr_pi1 | O19: =89.93/12.9 -> 6.9713178 | P19: 0 | Q19: 0 | R19: empty | S19: 1 | T19: 0 | U19: 0 | V19: 100 | W19: 100000 | X19: 100000 | Y19: empty | Z19: 1 | AA19: 0
